<sdf version='1.11'>
  <model name='g1_demo_cmd_vel'>
    <joint name="pelvis_world_joint" type="fixed">
      <parent>world</parent>
      <child>pelvis</child>
    </joint>

    <link name='pelvis'>
      <inertial>
        <pose>0 0 -0.076030060304142652 0 0 0</pose>
        <mass>3.8140000000000001</mass>
        <inertia>
          <ixx>0.010554882086086121</ixx>
          <ixy>0</ixy>
          <ixz>2.0999999999999998e-06</ixz>
          <iyy>0.0093147820860861284</iyy>
          <iyz>0</iyz>
          <izz>0.0079185000000000002</izz>
        </inertia>
      </inertial>
      <collision name='pelvis_contour_link_collision'>
        <pose>0 0 0 0 0 0</pose>
        <geometry>
          <mesh>
            <scale>1 1 1</scale>
            <uri>model://g1_description/meshes/pelvis_contour_link.STL</uri>
          </mesh>
        </geometry>
      </collision>
      <visual name='pelvis_visual'>
        <pose>0 0 0 0 0 0</pose>
        <geometry>
          <mesh>
            <scale>1 1 1</scale>
            <uri>model://g1_description/meshes/pelvis.STL</uri>
          </mesh>
        </geometry>
        <material>
          <diffuse>0.25 0.25 0.25 1</diffuse>
          <ambient>0.25 0.25 0.25 1</ambient>
        </material>
      </visual>
      <visual name='pelvis_contour_link_visual_1'>
        <pose>0 0 0 0 0 0</pose>
        <geometry>
          <mesh>
            <scale>1 1 1</scale>
            <uri>model://g1_description/meshes/pelvis_contour_link.STL</uri>
          </mesh>
        </geometry>
        <material>
          <diffuse>0.875 0.875 0.875 1</diffuse>
          <ambient>0.875 0.875 0.875 1</ambient>
        </material>
      </visual>
      <sensor name='pelvis_imu' type='imu'>
        <pose>0.045249999999999999 0 -0.083390000000000006 0 0 0</pose>
        <always_on>1</always_on>
        <update_rate>400</update_rate>
        <topic>/g1/imu/pelvis</topic>
        <visualize>false</visualize>
        <imu>
          <angular_velocity>
            <x><noise type='gaussian'><mean>0</mean><stddev>0.0005</stddev></noise></x>
            <y><noise type='gaussian'><mean>0</mean><stddev>0.0005</stddev></noise></y>
            <z><noise type='gaussian'><mean>0</mean><stddev>0.0005</stddev></noise></z>
          </angular_velocity>
          <linear_acceleration>
            <x><noise type='gaussian'><mean>0</mean><stddev>0.01</stddev></noise></x>
            <y><noise type='gaussian'><mean>0</mean><stddev>0.01</stddev></noise></y>
            <z><noise type='gaussian'><mean>0</mean><stddev>0.01</stddev></noise></z>
          </linear_acceleration>
        </imu>
      </sensor>
    </link>
    <joint name='left_hip_pitch_joint' type='revolute'>
      <pose relative_to='pelvis'>0 0.064451999999999995 -0.1027 0 0 0</pose>
      <parent>pelvis</parent>
      <child>left_hip_pitch_link</child>
      <axis>
        <xyz>0 1 0</xyz>
        <limit>
          <lower>-2.5306999999999999</lower>
          <upper>2.8797999999999999</upper>
          <effort>88</effort>
          <velocity>32</velocity>
        </limit>
        <dynamics>
          <spring_reference>0</spring_reference>
          <spring_stiffness>0</spring_stiffness>
        </dynamics>
      </axis>
    </joint>
    <link name='left_hip_pitch_link'>
      <pose relative_to='left_hip_pitch_joint'>0 0 0 0 0 0</pose>
      <inertial>
        <pose>0.0027409999999999999 0.047791 -0.02606 0 0 0</pose>
        <mass>1.3500000000000001</mass>
        <inertia>
          <ixx>0.0018109999999999999</ixx>
          <ixy>3.68e-05</ixy>
          <ixz>-3.4400000000000003e-05</ixz>
          <iyy>0.0014193000000000001</iyy>
          <iyz>0.00017100000000000001</iyz>
          <izz>0.0012811999999999999</izz>
        </inertia>
      </inertial>
      <collision name='left_hip_pitch_link_collision'>
        <pose>0 0 0 0 0 0</pose>
        <geometry>
          <mesh>
            <scale>1 1 1</scale>
            <uri>model://g1_description/meshes/left_hip_pitch_link.STL</uri>
          </mesh>
        </geometry>
      </collision>
      <visual name='left_hip_pitch_link_visual'>
        <pose>0 0 0 0 0 0</pose>
        <geometry>
          <mesh>
            <scale>1 1 1</scale>
            <uri>model://g1_description/meshes/left_hip_pitch_link.STL</uri>
          </mesh>
        </geometry>
        <material>
          <diffuse>0.25 0.25 0.25 1</diffuse>
          <ambient>0.25 0.25 0.25 1</ambient>
        </material>
      </visual>
    </link>
    <joint name='left_hip_roll_joint' type='revolute'>
      <pose relative_to='left_hip_pitch_link'>0 0.051999999999999998 -0.030464999999999999 0 -0.17490000000000003 0</pose>
      <parent>left_hip_pitch_link</parent>
      <child>left_hip_roll_link</child>
      <axis>
        <xyz>1 0 0</xyz>
        <limit>
          <lower>-0.52359999999999995</lower>
          <upper>2.9670999999999998</upper>
          <effort>139</effort>
          <velocity>20</velocity>
        </limit>
        <dynamics>
          <spring_reference>0</spring_reference>
          <spring_stiffness>0</spring_stiffness>
        </dynamics>
      </axis>
    </joint>
    <link name='left_hip_roll_link'>
      <pose relative_to='left_hip_roll_joint'>0 0 0 0 0 0</pose>
      <inertial>
        <pose>0.029812000000000002 -0.0010449999999999999 -0.087933999999999998 0 0 0</pose>
        <mass>1.52</mass>
        <inertia>
          <ixx>0.0023773000000000002</ixx>
          <ixy>-3.8e-06</ixy>
          <ixz>-0.00039080000000000001</ixz>
          <iyy>0.0024123</iyy>
          <iyz>1.84e-05</iyz>
          <izz>0.0016595</izz>
        </inertia>
      </inertial>
      <collision name='left_hip_roll_link_collision'>
        <pose>0 0 0 0 0 0</pose>
        <geometry>
          <mesh>
            <scale>1 1 1</scale>
            <uri>model://g1_description/meshes/left_hip_roll_link.STL</uri>
          </mesh>
        </geometry>
      </collision>
      <visual name='left_hip_roll_link_visual'>
        <pose>0 0 0 0 0 0</pose>
        <geometry>
          <mesh>
            <scale>1 1 1</scale>
            <uri>model://g1_description/meshes/left_hip_roll_link.STL</uri>
          </mesh>
        </geometry>
        <material>
          <diffuse>0.875 0.875 0.875 1</diffuse>
          <ambient>0.875 0.875 0.875 1</ambient>
        </material>
      </visual>
    </link>
    <joint name='left_hip_yaw_joint' type='revolute'>
      <pose relative_to='left_hip_roll_link'>0.025000999999999999 0 -0.12411999999999999 0 0 0</pose>
      <parent>left_hip_roll_link</parent>
      <child>left_hip_yaw_link</child>
      <axis>
        <xyz>0 0 1</xyz>
        <limit>
          <lower>-2.7576000000000001</lower>
          <upper>2.7576000000000001</upper>
          <effort>88</effort>
          <velocity>32</velocity>
        </limit>
        <dynamics>
          <spring_reference>0</spring_reference>
          <spring_stiffness>0</spring_stiffness>
        </dynamics>
      </axis>
    </joint>
    <link name='left_hip_yaw_link'>
      <pose relative_to='left_hip_yaw_joint'>0 0 0 0 0 0</pose>
      <inertial>
        <pose>-0.057709000000000003 -0.010980999999999999 -0.15078 0 0 0</pose>
        <mass>1.702</mass>
        <inertia>
          <ixx>0.0057774000000000002</ixx>
          <ixy>-0.00054109999999999998</ixy>
          <ixz>-0.0023947999999999999</ixz>
          <iyy>0.0076124000000000001</iyy>
          <iyz>-0.00070719999999999995</iyz>
          <izz>0.0031489999999999999</izz>
        </inertia>
      </inertial>
      <collision name='left_hip_yaw_link_collision'>
        <pose>0 0 0 0 0 0</pose>
        <geometry>
          <mesh>
            <scale>1 1 1</scale>
            <uri>model://g1_description/meshes/left_hip_yaw_link.STL</uri>
          </mesh>
        </geometry>
      </collision>
      <visual name='left_hip_yaw_link_visual'>
        <pose>0 0 0 0 0 0</pose>
        <geometry>
          <mesh>
            <scale>1 1 1</scale>
            <uri>model://g1_description/meshes/left_hip_yaw_link.STL</uri>
          </mesh>
        </geometry>
        <material>
          <diffuse>0.875 0.875 0.875 1</diffuse>
          <ambient>0.875 0.875 0.875 1</ambient>
        </material>
      </visual>
    </link>
    <joint name='left_knee_joint' type='revolute'>
      <pose relative_to='left_hip_yaw_link'>-0.078272999999999995 0.0021489 -0.17734 0 0.17490000000000003 0</pose>
      <parent>left_hip_yaw_link</parent>
      <child>left_knee_link</child>
      <axis>
        <xyz>0 1 0</xyz>
        <limit>
          <lower>-0.087266999999999997</lower>
          <upper>2.8797999999999999</upper>
          <effort>139</effort>
          <velocity>20</velocity>
        </limit>
        <dynamics>
          <spring_reference>0</spring_reference>
          <spring_stiffness>0</spring_stiffness>
        </dynamics>
      </axis>
    </joint>
    <link name='left_knee_link'>
      <pose relative_to='left_knee_joint'>0 0 0 0 0 0</pose>
      <inertial>
        <pose>0.005457 0.0039639999999999996 -0.12074 0 0 0</pose>
        <mass>1.9319999999999999</mass>
        <inertia>
          <ixx>0.011329000000000001</ixx>
          <ixy>4.8199999999999999e-05</ixy>
          <ixz>-4.49e-05</ixz>
          <iyy>0.011277000000000001</iyy>
          <iyz>-0.00071460000000000002</iyz>
          <izz>0.0015168</izz>
        </inertia>
      </inertial>
      <collision name='left_knee_link_collision'>
        <pose>0 0 0 0 0 0</pose>
        <geometry>
          <mesh>
            <scale>1 1 1</scale>
            <uri>model://g1_description/meshes/left_knee_link.STL</uri>
          </mesh>
        </geometry>
      </collision>
      <visual name='left_knee_link_visual'>
        <pose>0 0 0 0 0 0</pose>
        <geometry>
          <mesh>
            <scale>1 1 1</scale>
            <uri>model://g1_description/meshes/left_knee_link.STL</uri>
          </mesh>
        </geometry>
        <material>
          <diffuse>0.875 0.875 0.875 1</diffuse>
          <ambient>0.875 0.875 0.875 1</ambient>
        </material>
      </visual>
    </link>
    <joint name='left_ankle_pitch_joint' type='revolute'>
      <pose relative_to='left_knee_link'>0 -9.4444999999999994e-05 -0.30001 0 0 0</pose>
      <parent>left_knee_link</parent>
      <child>left_ankle_pitch_link</child>
      <axis>
        <xyz>0 1 0</xyz>
        <limit>
          <lower>-0.87266999999999995</lower>
          <upper>0.52359999999999995</upper>
          <effort>35</effort>
          <velocity>30</velocity>
        </limit>
        <dynamics>
          <spring_reference>0</spring_reference>
          <spring_stiffness>0</spring_stiffness>
        </dynamics>
      </axis>
    </joint>
    <link name='left_ankle_pitch_link'>
      <pose relative_to='left_ankle_pitch_joint'>0 0 0 0 0 0</pose>
      <inertial>
        <pose>-0.0072690000000000003 0 0.011136999999999999 0 0 0</pose>
        <mass>0.073999999999999996</mass>
        <inertia>
          <ixx>8.3999999999999992e-06</ixx>
          <ixy>0</ixy>
          <ixz>-2.9000000000000002e-06</ixz>
          <iyy>1.8899999999999999e-05</iyy>
          <iyz>0</iyz>
          <izz>1.26e-05</izz>
        </inertia>
      </inertial>
      <collision name='left_ankle_pitch_link_collision'>
        <pose>0 0 0 0 0 0</pose>
        <geometry>
          <mesh>
            <scale>1 1 1</scale>
            <uri>model://g1_description/meshes/left_ankle_pitch_link.STL</uri>
          </mesh>
        </geometry>
      </collision>
      <visual name='left_ankle_pitch_link_visual'>
        <pose>0 0 0 0 0 0</pose>
        <geometry>
          <mesh>
            <scale>1 1 1</scale>
            <uri>model://g1_description/meshes/left_ankle_pitch_link.STL</uri>
          </mesh>
        </geometry>
        <material>
          <diffuse>0.875 0.875 0.875 1</diffuse>
          <ambient>0.875 0.875 0.875 1</ambient>
        </material>
      </visual>
    </link>
    <joint name='left_ankle_roll_joint' type='revolute'>
      <pose relative_to='left_ankle_pitch_link'>0 0 -0.017558000000000001 0 0 0</pose>
      <parent>left_ankle_pitch_link</parent>
      <child>left_ankle_roll_link</child>
      <axis>
        <xyz>1 0 0</xyz>
        <limit>
          <lower>-0.26179999999999998</lower>
          <upper>0.26179999999999998</upper>
          <effort>35</effort>
          <velocity>8</velocity>
        </limit>
        <dynamics>
          <spring_reference>0</spring_reference>
          <spring_stiffness>0</spring_stiffness>
          <damping>1.5</damping>
          <friction>0.1</friction>
        </dynamics>
      </axis>
    </joint>
    <link name='left_ankle_roll_link'>
      <pose relative_to='left_ankle_roll_joint'>0 0 0 0 0 0</pose>
      <inertial>
        <pose>0.026505000000000001 0 -0.016424999999999999 0 0 0</pose>
        <mass>0.60799999999999998</mass>
        <inertia>
          <ixx>0.0002231</ixx>
          <ixy>1.9999999999999999e-07</ixy>
          <ixz>8.9099999999999997e-05</ixz>
          <iyy>0.0016161000000000001</iyy>
          <iyz>-9.9999999999999995e-08</iyz>
          <izz>0.0016666999999999999</izz>
        </inertia>
      </inertial>
      <collision name='left_ankle_roll_link_collision'>
        <pose>-0.050000000000000003 0.025000000000000001 -0.029999999999999999 0 0 0</pose>
        <geometry>
          <sphere>
            <radius>0.0050000000000000001</radius>
          </sphere>
        </geometry>
      </collision>
      <collision name='left_ankle_roll_link_collision_1'>
        <pose>-0.050000000000000003 -0.025000000000000001 -0.029999999999999999 0 0 0</pose>
        <geometry>
          <sphere>
            <radius>0.0050000000000000001</radius>
          </sphere>
        </geometry>
      </collision>
      <collision name='left_ankle_roll_link_collision_2'>
        <pose>0.12 0.029999999999999999 -0.029999999999999999 0 0 0</pose>
        <geometry>
          <sphere>
            <radius>0.0050000000000000001</radius>
          </sphere>
        </geometry>
      </collision>
      <collision name='left_ankle_roll_link_collision_3'>
        <pose>0.12 -0.029999999999999999 -0.029999999999999999 0 0 0</pose>
        <geometry>
          <sphere>
            <radius>0.0050000000000000001</radius>
          </sphere>
        </geometry>
      </collision>
      <visual name='left_ankle_roll_link_visual'>
        <pose>0 0 0 0 0 0</pose>
        <geometry>
          <mesh>
            <scale>1 1 1</scale>
            <uri>model://g1_description/meshes/left_ankle_roll_link.STL</uri>
          </mesh>
        </geometry>
        <material>
          <diffuse>0.25 0.25 0.25 1</diffuse>
          <ambient>0.25 0.25 0.25 1</ambient>
        </material>
      </visual>
    </link>
    <joint name='right_hip_pitch_joint' type='revolute'>
      <pose relative_to='pelvis'>0 -0.064451999999999995 -0.1027 0 0 0</pose>
      <parent>pelvis</parent>
      <child>right_hip_pitch_link</child>
      <axis>
        <xyz>0 1 0</xyz>
        <limit>
          <lower>-2.5306999999999999</lower>
          <upper>2.8797999999999999</upper>
          <effort>88</effort>
          <velocity>32</velocity>
        </limit>
        <dynamics>
          <spring_reference>0</spring_reference>
          <spring_stiffness>0</spring_stiffness>
        </dynamics>
      </axis>
    </joint>
    <link name='right_hip_pitch_link'>
      <pose relative_to='right_hip_pitch_joint'>0 0 0 0 0 0</pose>
      <inertial>
        <pose>0.0027409999999999999 -0.047791 -0.02606 0 0 0</pose>
        <mass>1.3500000000000001</mass>
        <inertia>
          <ixx>0.0018109999999999999</ixx>
          <ixy>-3.68e-05</ixy>
          <ixz>-3.4400000000000003e-05</ixz>
          <iyy>0.0014193000000000001</iyy>
          <iyz>-0.00017100000000000001</iyz>
          <izz>0.0012811999999999999</izz>
        </inertia>
      </inertial>
      <collision name='right_hip_pitch_link_collision'>
        <pose>0 0 0 0 0 0</pose>
        <geometry>
          <mesh>
            <scale>1 1 1</scale>
            <uri>model://g1_description/meshes/right_hip_pitch_link.STL</uri>
          </mesh>
        </geometry>
      </collision>
      <visual name='right_hip_pitch_link_visual'>
        <pose>0 0 0 0 0 0</pose>
        <geometry>
          <mesh>
            <scale>1 1 1</scale>
            <uri>model://g1_description/meshes/right_hip_pitch_link.STL</uri>
          </mesh>
        </geometry>
        <material>
          <diffuse>0.25 0.25 0.25 1</diffuse>
          <ambient>0.25 0.25 0.25 1</ambient>
        </material>
      </visual>
    </link>
    <joint name='right_hip_roll_joint' type='revolute'>
      <pose relative_to='right_hip_pitch_link'>0 -0.051999999999999998 -0.030464999999999999 0 -0.17490000000000003 0</pose>
      <parent>right_hip_pitch_link</parent>
      <child>right_hip_roll_link</child>
      <axis>
        <xyz>1 0 0</xyz>
        <limit>
          <lower>-2.9670999999999998</lower>
          <upper>0.52359999999999995</upper>
          <effort>139</effort>
          <velocity>20</velocity>
        </limit>
        <dynamics>
          <spring_reference>0</spring_reference>
          <spring_stiffness>0</spring_stiffness>
        </dynamics>
      </axis>
    </joint>
    <link name='right_hip_roll_link'>
      <pose relative_to='right_hip_roll_joint'>0 0 0 0 0 0</pose>
      <inertial>
        <pose>0.029812000000000002 0.0010449999999999999 -0.087933999999999998 0 0 0</pose>
        <mass>1.52</mass>
        <inertia>
          <ixx>0.0023773000000000002</ixx>
          <ixy>3.8e-06</ixy>
          <ixz>-0.00039080000000000001</ixz>
          <iyy>0.0024123</iyy>
          <iyz>-1.84e-05</iyz>
          <izz>0.0016595</izz>
        </inertia>
      </inertial>
      <collision name='right_hip_roll_link_collision'>
        <pose>0 0 0 0 0 0</pose>
        <geometry>
          <mesh>
            <scale>1 1 1</scale>
            <uri>model://g1_description/meshes/right_hip_roll_link.STL</uri>
          </mesh>
        </geometry>
      </collision>
      <visual name='right_hip_roll_link_visual'>
        <pose>0 0 0 0 0 0</pose>
        <geometry>
          <mesh>
            <scale>1 1 1</scale>
            <uri>model://g1_description/meshes/right_hip_roll_link.STL</uri>
          </mesh>
        </geometry>
        <material>
          <diffuse>0.875 0.875 0.875 1</diffuse>
          <ambient>0.875 0.875 0.875 1</ambient>
        </material>
      </visual>
    </link>
    <joint name='right_hip_yaw_joint' type='revolute'>
      <pose relative_to='right_hip_roll_link'>0.025000999999999999 0 -0.12411999999999999 0 0 0</pose>
      <parent>right_hip_roll_link</parent>
      <child>right_hip_yaw_link</child>
      <axis>
        <xyz>0 0 1</xyz>
        <limit>
          <lower>-2.7576000000000001</lower>
          <upper>2.7576000000000001</upper>
          <effort>88</effort>
          <velocity>32</velocity>
        </limit>
        <dynamics>
          <spring_reference>0</spring_reference>
          <spring_stiffness>0</spring_stiffness>
        </dynamics>
      </axis>
    </joint>
    <link name='right_hip_yaw_link'>
      <pose relative_to='right_hip_yaw_joint'>0 0 0 0 0 0</pose>
      <inertial>
        <pose>-0.057709000000000003 0.010980999999999999 -0.15078 0 0 0</pose>
        <mass>1.702</mass>
        <inertia>
          <ixx>0.0057774000000000002</ixx>
          <ixy>0.00054109999999999998</ixy>
          <ixz>-0.0023947999999999999</ixz>
          <iyy>0.0076124000000000001</iyy>
          <iyz>0.00070719999999999995</iyz>
          <izz>0.0031489999999999999</izz>
        </inertia>
      </inertial>
      <collision name='right_hip_yaw_link_collision'>
        <pose>0 0 0 0 0 0</pose>
        <geometry>
          <mesh>
            <scale>1 1 1</scale>
            <uri>model://g1_description/meshes/right_hip_yaw_link.STL</uri>
          </mesh>
        </geometry>
      </collision>
      <visual name='right_hip_yaw_link_visual'>
        <pose>0 0 0 0 0 0</pose>
        <geometry>
          <mesh>
            <scale>1 1 1</scale>
            <uri>model://g1_description/meshes/right_hip_yaw_link.STL</uri>
          </mesh>
        </geometry>
        <material>
          <diffuse>0.875 0.875 0.875 1</diffuse>
          <ambient>0.875 0.875 0.875 1</ambient>
        </material>
      </visual>
    </link>
    <joint name='right_knee_joint' type='revolute'>
      <pose relative_to='right_hip_yaw_link'>-0.078272999999999995 -0.0021489 -0.17734 0 0.17490000000000003 0</pose>
      <parent>right_hip_yaw_link</parent>
      <child>right_knee_link</child>
      <axis>
        <xyz>0 1 0</xyz>
        <limit>
          <lower>-0.087266999999999997</lower>
          <upper>2.8797999999999999</upper>
          <effort>139</effort>
          <velocity>20</velocity>
        </limit>
        <dynamics>
          <spring_reference>0</spring_reference>
          <spring_stiffness>0</spring_stiffness>
        </dynamics>
      </axis>
    </joint>
    <link name='right_knee_link'>
      <pose relative_to='right_knee_joint'>0 0 0 0 0 0</pose>
      <inertial>
        <pose>0.005457 -0.0039639999999999996 -0.12074 0 0 0</pose>
        <mass>1.9319999999999999</mass>
        <inertia>
          <ixx>0.011329000000000001</ixx>
          <ixy>-4.8199999999999999e-05</ixy>
          <ixz>4.49e-05</ixz>
          <iyy>0.011277000000000001</iyy>
          <iyz>0.00071460000000000002</iyz>
          <izz>0.0015168</izz>
        </inertia>
      </inertial>
      <collision name='right_knee_link_collision'>
        <pose>0 0 0 0 0 0</pose>
        <geometry>
          <mesh>
            <scale>1 1 1</scale>
            <uri>model://g1_description/meshes/right_knee_link.STL</uri>
          </mesh>
        </geometry>
      </collision>
      <visual name='right_knee_link_visual'>
        <pose>0 0 0 0 0 0</pose>
        <geometry>
          <mesh>
            <scale>1 1 1</scale>
            <uri>model://g1_description/meshes/right_knee_link.STL</uri>
          </mesh>
        </geometry>
        <material>
          <diffuse>0.875 0.875 0.875 1</diffuse>
          <ambient>0.875 0.875 0.875 1</ambient>
        </material>
      </visual>
    </link>
    <joint name='right_ankle_pitch_joint' type='revolute'>
      <pose relative_to='right_knee_link'>0 9.4444999999999994e-05 -0.30001 0 0 0</pose>
      <parent>right_knee_link</parent>
      <child>right_ankle_pitch_link</child>
      <axis>
        <xyz>0 1 0</xyz>
        <limit>
          <lower>-0.87266999999999995</lower>
          <upper>0.52359999999999995</upper>
          <effort>35</effort>
          <velocity>30</velocity>
        </limit>
        <dynamics>
          <spring_reference>0</spring_reference>
          <spring_stiffness>0</spring_stiffness>
        </dynamics>
      </axis>
    </joint>
    <link name='right_ankle_pitch_link'>
      <pose relative_to='right_ankle_pitch_joint'>0 0 0 0 0 0</pose>
      <inertial>
        <pose>-0.0072690000000000003 0 0.011136999999999999 0 0 0</pose>
        <mass>0.073999999999999996</mass>
        <inertia>
          <ixx>8.3999999999999992e-06</ixx>
          <ixy>0</ixy>
          <ixz>-2.9000000000000002e-06</ixz>
          <iyy>1.8899999999999999e-05</iyy>
          <iyz>0</iyz>
          <izz>1.26e-05</izz>
        </inertia>
      </inertial>
      <collision name='right_ankle_pitch_link_collision'>
        <pose>0 0 0 0 0 0</pose>
        <geometry>
          <mesh>
            <scale>1 1 1</scale>
            <uri>model://g1_description/meshes/right_ankle_pitch_link.STL</uri>
          </mesh>
        </geometry>
      </collision>
      <visual name='right_ankle_pitch_link_visual'>
        <pose>0 0 0 0 0 0</pose>
        <geometry>
          <mesh>
            <scale>1 1 1</scale>
            <uri>model://g1_description/meshes/right_ankle_pitch_link.STL</uri>
          </mesh>
        </geometry>
        <material>
          <diffuse>0.875 0.875 0.875 1</diffuse>
          <ambient>0.875 0.875 0.875 1</ambient>
        </material>
      </visual>
    </link>
    <joint name='right_ankle_roll_joint' type='revolute'>
      <pose relative_to='right_ankle_pitch_link'>0 0 -0.017558000000000001 0 0 0</pose>
      <parent>right_ankle_pitch_link</parent>
      <child>right_ankle_roll_link</child>
      <axis>
        <xyz>1 0 0</xyz>
        <limit>
          <lower>-0.26179999999999998</lower>
          <upper>0.26179999999999998</upper>
          <effort>35</effort>
          <velocity>8</velocity>
        </limit>
        <dynamics>
          <spring_reference>0</spring_reference>
          <spring_stiffness>0</spring_stiffness>
          <damping>1.5</damping>
          <friction>0.1</friction>
        </dynamics>
      </axis>
    </joint>
    <link name='right_ankle_roll_link'>
      <pose relative_to='right_ankle_roll_joint'>0 0 0 0 0 0</pose>
      <inertial>
        <pose>0.026505000000000001 0 -0.016424999999999999 0 0 0</pose>
        <mass>0.60799999999999998</mass>
        <inertia>
          <ixx>0.0002231</ixx>
          <ixy>-1.9999999999999999e-07</ixy>
          <ixz>8.9099999999999997e-05</ixz>
          <iyy>0.0016161000000000001</iyy>
          <iyz>9.9999999999999995e-08</iyz>
          <izz>0.0016666999999999999</izz>
        </inertia>
      </inertial>
      <collision name='right_ankle_roll_link_collision'>
        <pose>-0.050000000000000003 0.025000000000000001 -0.029999999999999999 0 0 0</pose>
        <geometry>
          <sphere>
            <radius>0.0050000000000000001</radius>
          </sphere>
        </geometry>
      </collision>
      <collision name='right_ankle_roll_link_collision_1'>
        <pose>-0.050000000000000003 -0.025000000000000001 -0.029999999999999999 0 0 0</pose>
        <geometry>
          <sphere>
            <radius>0.0050000000000000001</radius>
          </sphere>
        </geometry>
      </collision>
      <collision name='right_ankle_roll_link_collision_2'>
        <pose>0.12 0.029999999999999999 -0.029999999999999999 0 0 0</pose>
        <geometry>
          <sphere>
            <radius>0.0050000000000000001</radius>
          </sphere>
        </geometry>
      </collision>
      <collision name='right_ankle_roll_link_collision_3'>
        <pose>0.12 -0.029999999999999999 -0.029999999999999999 0 0 0</pose>
        <geometry>
          <sphere>
            <radius>0.0050000000000000001</radius>
          </sphere>
        </geometry>
      </collision>
      <visual name='right_ankle_roll_link_visual'>
        <pose>0 0 0 0 0 0</pose>
        <geometry>
          <mesh>
            <scale>1 1 1</scale>
            <uri>model://g1_description/meshes/right_ankle_roll_link.STL</uri>
          </mesh>
        </geometry>
        <material>
          <diffuse>0.25 0.25 0.25 1</diffuse>
          <ambient>0.25 0.25 0.25 1</ambient>
        </material>
      </visual>
    </link>
    <joint name='waist_yaw_joint' type='revolute'>
      <pose relative_to='pelvis'>0 0 0 0 0 0</pose>
      <parent>pelvis</parent>
      <child>waist_yaw_link</child>
      <axis>
        <xyz>0 0 1</xyz>
        <limit>
          <lower>-2.6179999999999999</lower>
          <upper>2.6179999999999999</upper>
          <effort>88</effort>
          <velocity>32</velocity>
        </limit>
        <dynamics>
          <spring_reference>0</spring_reference>
          <spring_stiffness>0</spring_stiffness>
        </dynamics>
      </axis>
    </joint>
    <link name='waist_yaw_link'>
      <pose relative_to='waist_yaw_joint'>0 0 0 0 0 0</pose>
      <inertial>
        <pose>0.0034940000000000001 0.000233 0.018034000000000001 0 0 0</pose>
        <mass>0.214</mass>
        <inertia>
          <ixx>0.00010673</ixx>
          <ixy>2.7030000000000002e-06</ixy>
          <ixz>-7.6310000000000003e-06</ixz>
          <iyy>0.00010422</iyy>
          <iyz>-2.0100000000000001e-07</iyz>
          <izz>0.00016249999999999999</izz>
        </inertia>
      </inertial>
      <visual name='waist_yaw_link_visual'>
        <pose>0 0 0 0 0 0</pose>
        <geometry>
          <mesh>
            <scale>1 1 1</scale>
            <uri>model://g1_description/meshes/waist_yaw_link_rev_1_0.STL</uri>
          </mesh>
        </geometry>
        <material>
          <diffuse>0.875 0.875 0.875 1</diffuse>
          <ambient>0.875 0.875 0.875 1</ambient>
        </material>
      </visual>
    </link>
    <joint name='waist_roll_joint' type='revolute'>
      <pose relative_to='waist_yaw_link'>-0.0039635 0 0.043999999999999997 0 0 0</pose>
      <parent>waist_yaw_link</parent>
      <child>waist_roll_link</child>
      <axis>
        <xyz>1 0 0</xyz>
        <limit>
          <lower>-0.52000000000000002</lower>
          <upper>0.52000000000000002</upper>
          <effort>35</effort>
          <velocity>30</velocity>
        </limit>
        <dynamics>
          <spring_reference>0</spring_reference>
          <spring_stiffness>0</spring_stiffness>
        </dynamics>
      </axis>
    </joint>
    <link name='waist_roll_link'>
      <pose relative_to='waist_roll_joint'>0 0 0 0 0 0</pose>
      <inertial>
        <pose>0 2.3e-05 0 0 0 0</pose>
        <mass>0.085999999999999993</mass>
        <inertia>
          <ixx>7.0790000000000003e-06</ixx>
          <ixy>0</ixy>
          <ixz>0</ixz>
          <iyy>6.3389999999999998e-06</iyy>
          <iyz>0</iyz>
          <izz>8.2449999999999998e-06</izz>
        </inertia>
      </inertial>
      <visual name='waist_roll_link_visual'>
        <pose>0 0 0 0 0 0</pose>
        <geometry>
          <mesh>
            <scale>1 1 1</scale>
            <uri>model://g1_description/meshes/waist_roll_link_rev_1_0.STL</uri>
          </mesh>
        </geometry>
        <material>
          <diffuse>0.875 0.875 0.875 1</diffuse>
          <ambient>0.875 0.875 0.875 1</ambient>
        </material>
      </visual>
    </link>
    <joint name='waist_pitch_joint' type='revolute'>
      <pose relative_to='waist_roll_link'>0 0 0 0 0 0</pose>
      <parent>waist_roll_link</parent>
      <child>torso_link</child>
      <axis>
        <xyz>0 1 0</xyz>
        <limit>
          <lower>-0.52000000000000002</lower>
          <upper>0.52000000000000002</upper>
          <effort>35</effort>
          <velocity>30</velocity>
        </limit>
        <dynamics>
          <spring_reference>0</spring_reference>
          <spring_stiffness>0</spring_stiffness>
        </dynamics>
      </axis>
    </joint>
    <link name='torso_link'>
      <pose relative_to='waist_pitch_joint'>0 0 0 0 0 0</pose>
      <inertial>
        <pose>0.00203133446334911 0.00033972674939234998 0.18459714519636691 0 0 0</pose>
        <mass>7.8170000000000011</mass>
        <inertia>
          <ixx>0.1216465196429006</ixx>
          <ixy>3.1110210297586289e-05</ixy>
          <ixz>-0.0037428195854218851</ixz>
          <iyy>0.10977258485702911</iyy>
          <iyz>-1.5429925458139451e-05</iyz>
          <izz>0.02752191941535314</izz>
        </inertia>
      </inertial>
      <collision name='torso_link_collision'>
        <pose>0 0 0 0 0 0</pose>
        <geometry>
          <mesh>
            <scale>1 1 1</scale>
            <uri>model://g1_description/meshes/torso_link_rev_1_0.STL</uri>
          </mesh>
        </geometry>
      </collision>
      <collision name='torso_link_fixed_joint_lump__head_link_collision_1'>
        <pose>0.0039635 0 -0.043999999999999997 0 0 0</pose>
        <geometry>
          <mesh>
            <scale>1 1 1</scale>
            <uri>model://g1_description/meshes/head_link.STL</uri>
          </mesh>
        </geometry>
      </collision>
      <collision name='torso_link_fixed_joint_lump__logo_link_collision_2'>
        <pose>0.0039635 0 -0.043999999999999997 0 0 0</pose>
        <geometry>
          <mesh>
            <scale>1 1 1</scale>
            <uri>model://g1_description/meshes/logo_link.STL</uri>
          </mesh>
        </geometry>
      </collision>
      <visual name='torso_link_visual'>
        <pose>0 0 0 0 0 0</pose>
        <geometry>
          <mesh>
            <scale>1 1 1</scale>
            <uri>model://g1_description/meshes/torso_link_rev_1_0.STL</uri>
          </mesh>
        </geometry>
        <material>
          <diffuse>0.875 0.875 0.875 1</diffuse>
          <ambient>0.875 0.875 0.875 1</ambient>
        </material>
      </visual>
      <visual name='torso_link_fixed_joint_lump__head_link_visual_1'>
        <pose>0.0039635 0 -0.043999999999999997 0 0 0</pose>
        <geometry>
          <mesh>
            <scale>1 1 1</scale>
            <uri>model://g1_description/meshes/head_link.STL</uri>
          </mesh>
        </geometry>
        <material>
          <diffuse>0.25 0.25 0.25 1</diffuse>
          <ambient>0.25 0.25 0.25 1</ambient>
        </material>
      </visual>
      <visual name='torso_link_fixed_joint_lump__logo_link_visual_2'>
        <pose>0.0039635 0 -0.043999999999999997 0 0 0</pose>
        <geometry>
          <mesh>
            <scale>1 1 1</scale>
            <uri>model://g1_description/meshes/logo_link.STL</uri>
          </mesh>
        </geometry>
        <material>
          <diffuse>0.25 0.25 0.25 1</diffuse>
          <ambient>0.25 0.25 0.25 1</ambient>
        </material>
      </visual>
      <sensor name='torso_imu' type='imu'>
        <pose>-0.03959 -0.0022399999999999998 0.14792 0 0 0</pose>
        <always_on>1</always_on>
        <update_rate>400</update_rate>
        <topic>/g1/imu/torso</topic>
        <visualize>false</visualize>
        <imu>
          <angular_velocity>
            <x><noise type='gaussian'><mean>0</mean><stddev>0.0005</stddev></noise></x>
            <y><noise type='gaussian'><mean>0</mean><stddev>0.0005</stddev></noise></y>
            <z><noise type='gaussian'><mean>0</mean><stddev>0.0005</stddev></noise></z>
          </angular_velocity>
          <linear_acceleration>
            <x><noise type='gaussian'><mean>0</mean><stddev>0.01</stddev></noise></x>
            <y><noise type='gaussian'><mean>0</mean><stddev>0.01</stddev></noise></y>
            <z><noise type='gaussian'><mean>0</mean><stddev>0.01</stddev></noise></z>
          </linear_acceleration>
        </imu>
      </sensor>
    </link>
    <joint name='left_shoulder_pitch_joint' type='revolute'>
      <pose relative_to='torso_link'>0.0039563000000000003 0.10022 0.24778 0.27931000000000011 5.4949000000000032e-05 -0.00019159</pose>
      <parent>torso_link</parent>
      <child>left_shoulder_pitch_link</child>
      <axis>
        <xyz>0 1 0</xyz>
        <limit>
          <lower>-3.0891999999999999</lower>
          <upper>2.6703999999999999</upper>
          <effort>25</effort>
          <velocity>37</velocity>
        </limit>
        <dynamics>
          <spring_reference>0</spring_reference>
          <spring_stiffness>0</spring_stiffness>
        </dynamics>
      </axis>
    </joint>
    <link name='left_shoulder_pitch_link'>
      <pose relative_to='left_shoulder_pitch_joint'>0 0 0 0 0 0</pose>
      <inertial>
        <pose>0 0.035892 -0.011627999999999999 0 0 0</pose>
        <mass>0.71799999999999997</mass>
        <inertia>
          <ixx>0.00042910000000000002</ixx>
          <ixy>-9.2e-06</ixy>
          <ixz>6.3999999999999997e-06</ixz>
          <iyy>0.00045300000000000001</iyy>
          <iyz>2.26e-05</iyz>
          <izz>0.00042299999999999998</izz>
        </inertia>
      </inertial>
      <collision name='left_shoulder_pitch_link_collision'>
        <pose>0 0.040000000000000001 -0.01 0 1.5707963267948966 0</pose>
        <geometry>
          <cylinder>
            <length>0.050000000000000003</length>
            <radius>0.029999999999999999</radius>
          </cylinder>
        </geometry>
      </collision>
      <visual name='left_shoulder_pitch_link_visual'>
        <pose>0 0 0 0 0 0</pose>
        <geometry>
          <mesh>
            <scale>1 1 1</scale>
            <uri>model://g1_description/meshes/left_shoulder_pitch_link.STL</uri>
          </mesh>
        </geometry>
        <material>
          <diffuse>0.875 0.875 0.875 1</diffuse>
          <ambient>0.875 0.875 0.875 1</ambient>
        </material>
      </visual>
    </link>
    <joint name='left_shoulder_roll_joint' type='revolute'>
      <pose relative_to='left_shoulder_pitch_link'>0 0.037999999999999999 -0.013831 -0.27925000000000011 0 0</pose>
      <parent>left_shoulder_pitch_link</parent>
      <child>left_shoulder_roll_link</child>
      <axis>
        <xyz>1 0 0</xyz>
        <limit>
          <lower>-1.5882000000000001</lower>
          <upper>2.2515000000000001</upper>
          <effort>25</effort>
          <velocity>37</velocity>
        </limit>
        <dynamics>
          <spring_reference>0</spring_reference>
          <spring_stiffness>0</spring_stiffness>
        </dynamics>
      </axis>
    </joint>
    <link name='left_shoulder_roll_link'>
      <pose relative_to='left_shoulder_roll_joint'>0 0 0 0 0 0</pose>
      <inertial>
        <pose>-0.00022699999999999999 0.0072700000000000004 -0.063242999999999994 0 0 0</pose>
        <mass>0.64300000000000002</mass>
        <inertia>
          <ixx>0.0006177</ixx>
          <ixy>-9.9999999999999995e-07</ixy>
          <ixz>8.6999999999999997e-06</ixz>
          <iyy>0.0006912</iyy>
          <iyz>-5.3000000000000001e-06</iyz>
          <izz>0.00038939999999999998</izz>
        </inertia>
      </inertial>
      <collision name='left_shoulder_roll_link_collision'>
        <pose>-0.0040000000000000001 0.0060000000000000001 -0.052999999999999999 0 0 0</pose>
        <geometry>
          <cylinder>
            <length>0.029999999999999999</length>
            <radius>0.029999999999999999</radius>
          </cylinder>
        </geometry>
      </collision>
      <visual name='left_shoulder_roll_link_visual'>
        <pose>0 0 0 0 0 0</pose>
        <geometry>
          <mesh>
            <scale>1 1 1</scale>
            <uri>model://g1_description/meshes/left_shoulder_roll_link.STL</uri>
          </mesh>
        </geometry>
        <material>
          <diffuse>0.875 0.875 0.875 1</diffuse>
          <ambient>0.875 0.875 0.875 1</ambient>
        </material>
      </visual>
    </link>
    <joint name='left_shoulder_yaw_joint' type='revolute'>
      <pose relative_to='left_shoulder_roll_link'>0 0.0062399999999999999 -0.1032 0 0 0</pose>
      <parent>left_shoulder_roll_link</parent>
      <child>left_shoulder_yaw_link</child>
      <axis>
        <xyz>0 0 1</xyz>
        <limit>
          <lower>-2.6179999999999999</lower>
          <upper>2.6179999999999999</upper>
          <effort>25</effort>
          <velocity>37</velocity>
        </limit>
        <dynamics>
          <spring_reference>0</spring_reference>
          <spring_stiffness>0</spring_stiffness>
        </dynamics>
      </axis>
    </joint>
    <link name='left_shoulder_yaw_link'>
      <pose relative_to='left_shoulder_yaw_joint'>0 0 0 0 0 0</pose>
      <inertial>
        <pose>0.010773 -0.0029489999999999998 -0.072009000000000004 0 0 0</pose>
        <mass>0.73399999999999999</mass>
        <inertia>
          <ixx>0.00099879999999999999</ixx>
          <ixy>7.9000000000000006e-06</ixy>
          <ixz>0.00014119999999999999</ixz>
          <iyy>0.0010605</iyy>
          <iyz>-2.8600000000000001e-05</iyz>
          <izz>0.00043540000000000001</izz>
        </inertia>
      </inertial>
      <collision name='left_shoulder_yaw_link_collision'>
        <pose>0 0 0 0 0 0</pose>
        <geometry>
          <mesh>
            <scale>1 1 1</scale>
            <uri>model://g1_description/meshes/left_shoulder_yaw_link.STL</uri>
          </mesh>
        </geometry>
      </collision>
      <visual name='left_shoulder_yaw_link_visual'>
        <pose>0 0 0 0 0 0</pose>
        <geometry>
          <mesh>
            <scale>1 1 1</scale>
            <uri>model://g1_description/meshes/left_shoulder_yaw_link.STL</uri>
          </mesh>
        </geometry>
        <material>
          <diffuse>0.875 0.875 0.875 1</diffuse>
          <ambient>0.875 0.875 0.875 1</ambient>
        </material>
      </visual>
    </link>
    <joint name='left_elbow_joint' type='revolute'>
      <pose relative_to='left_shoulder_yaw_link'>0.015782999999999998 0 -0.080518000000000006 0 0 0</pose>
      <parent>left_shoulder_yaw_link</parent>
      <child>left_elbow_link</child>
      <axis>
        <xyz>0 1 0</xyz>
        <limit>
          <lower>-1.0471999999999999</lower>
          <upper>2.0943999999999998</upper>
          <effort>25</effort>
          <velocity>37</velocity>
        </limit>
        <dynamics>
          <spring_reference>0</spring_reference>
          <spring_stiffness>0</spring_stiffness>
        </dynamics>
      </axis>
    </joint>
    <link name='left_elbow_link'>
      <pose relative_to='left_elbow_joint'>0 0 0 0 0 0</pose>
      <inertial>
        <pose>0.064956 0.0044539999999999996 -0.010062 0 0 0</pose>
        <mass>0.59999999999999998</mass>
        <inertia>
          <ixx>0.00028909999999999998</ixx>
          <ixy>6.5300000000000002e-05</ixy>
          <ixz>1.7200000000000001e-05</ixz>
          <iyy>0.00041520000000000001</iyy>
          <iyz>-5.5999999999999997e-06</iyz>
          <izz>0.00041970000000000001</izz>
        </inertia>
      </inertial>
      <collision name='left_elbow_link_collision'>
        <pose>0 0 0 0 0 0</pose>
        <geometry>
          <mesh>
            <scale>1 1 1</scale>
            <uri>model://g1_description/meshes/left_elbow_link.STL</uri>
          </mesh>
        </geometry>
      </collision>
      <visual name='left_elbow_link_visual'>
        <pose>0 0 0 0 0 0</pose>
        <geometry>
          <mesh>
            <scale>1 1 1</scale>
            <uri>model://g1_description/meshes/left_elbow_link.STL</uri>
          </mesh>
        </geometry>
        <material>
          <diffuse>0.875 0.875 0.875 1</diffuse>
          <ambient>0.875 0.875 0.875 1</ambient>
        </material>
      </visual>
    </link>
    <joint name='left_wrist_roll_joint' type='revolute'>
      <pose relative_to='left_elbow_link'>0.10000000000000001 0.00188791 -0.01 0 0 0</pose>
      <parent>left_elbow_link</parent>
      <child>left_wrist_roll_link</child>
      <axis>
        <xyz>1 0 0</xyz>
        <limit>
          <lower>-1.9722220539999999</lower>
          <upper>1.9722220539999999</upper>
          <effort>25</effort>
          <velocity>37</velocity>
        </limit>
        <dynamics>
          <spring_reference>0</spring_reference>
          <spring_stiffness>0</spring_stiffness>
        </dynamics>
      </axis>
    </joint>
    <link name='left_wrist_roll_link'>
      <pose relative_to='left_wrist_roll_joint'>0 0 0 0 0 0</pose>
      <inertial>
        <pose>0.017139447780000001 0.00053759094000000005 4.8864000000000001e-07 0 0 0</pose>
        <mass>0.085444980000000004</mass>
        <inertia>
          <ixx>4.8215440230000001e-05</ixx>
          <ixy>-4.2451102099999998e-06</ixy>
          <ixz>5.1059899999999997e-09</ixz>
          <iyy>3.7228990929999999e-05</iyy>
          <iyz>-1.2352500000000001e-09</iyz>
          <izz>5.4821065410000003e-05</izz>
        </inertia>
      </inertial>
      <collision name='left_wrist_roll_link_collision'>
        <pose>0 0 0 0 0 0</pose>
        <geometry>
          <mesh>
            <scale>1 1 1</scale>
            <uri>model://g1_description/meshes/left_wrist_roll_link.STL</uri>
          </mesh>
        </geometry>
      </collision>
      <visual name='left_wrist_roll_link_visual'>
        <pose>0 0 0 0 0 0</pose>
        <geometry>
          <mesh>
            <scale>1 1 1</scale>
            <uri>model://g1_description/meshes/left_wrist_roll_link.STL</uri>
          </mesh>
        </geometry>
        <material>
          <diffuse>0.875 0.875 0.875 1</diffuse>
          <ambient>0.875 0.875 0.875 1</ambient>
        </material>
      </visual>
    </link>
    <joint name='left_wrist_pitch_joint' type='revolute'>
      <pose relative_to='left_wrist_roll_link'>0.037999999999999999 0 0 0 0 0</pose>
      <parent>left_wrist_roll_link</parent>
      <child>left_wrist_pitch_link</child>
      <axis>
        <xyz>0 1 0</xyz>
        <limit>
          <lower>-1.6144295580000001</lower>
          <upper>1.6144295580000001</upper>
          <effort>5</effort>
          <velocity>22</velocity>
        </limit>
        <dynamics>
          <spring_reference>0</spring_reference>
          <spring_stiffness>0</spring_stiffness>
        </dynamics>
      </axis>
    </joint>
    <link name='left_wrist_pitch_link'>
      <pose relative_to='left_wrist_pitch_joint'>0 0 0 0 0 0</pose>
      <inertial>
        <pose>0.022999898370000001 -0.00111685314 -0.0011165809599999999 0 0 0</pose>
        <mass>0.48404955999999999</mass>
        <inertia>
          <ixx>0.00016579646273</ixx>
          <ixy>-1.231206746e-05</ixy>
          <ixz>1.231699194e-05</ixz>
          <iyy>0.00042954057410000003</iyy>
          <iyz>8.1417711999999998e-07</iyz>
          <izz>0.00042953697654000002</izz>
        </inertia>
      </inertial>
      <collision name='left_wrist_pitch_link_collision'>
        <pose>0 0 0 0 0 0</pose>
        <geometry>
          <mesh>
            <scale>1 1 1</scale>
            <uri>model://g1_description/meshes/left_wrist_pitch_link.STL</uri>
          </mesh>
        </geometry>
      </collision>
      <visual name='left_wrist_pitch_link_visual'>
        <pose>0 0 0 0 0 0</pose>
        <geometry>
          <mesh>
            <scale>1 1 1</scale>
            <uri>model://g1_description/meshes/left_wrist_pitch_link.STL</uri>
          </mesh>
        </geometry>
        <material>
          <diffuse>0.875 0.875 0.875 1</diffuse>
          <ambient>0.875 0.875 0.875 1</ambient>
        </material>
      </visual>
    </link>
    <joint name='left_wrist_yaw_joint' type='revolute'>
      <pose relative_to='left_wrist_pitch_link'>0.045999999999999999 0 0 0 0 0</pose>
      <parent>left_wrist_pitch_link</parent>
      <child>left_wrist_yaw_link</child>
      <axis>
        <xyz>0 0 1</xyz>
        <limit>
          <lower>-1.6144295580000001</lower>
          <upper>1.6144295580000001</upper>
          <effort>5</effort>
          <velocity>22</velocity>
        </limit>
        <dynamics>
          <spring_reference>0</spring_reference>
          <spring_stiffness>0</spring_stiffness>
        </dynamics>
      </axis>
    </joint>
    <link name='left_wrist_yaw_link'>
      <pose relative_to='left_wrist_yaw_joint'>0 0 0 0 0 0</pose>
      <inertial>
        <pose>0.070824430201051378 0.00019174529120036591 0.0016174161391889761 0 0 0</pose>
        <mass>0.25457647</mass>
        <inertia>
          <ixx>0.00015044517917257641</ixx>
          <ixy>3.7602754090026117e-05</ixy>
          <ixz>-2.9549415859057682e-06</ixz>
          <iyy>0.00064311326853337463</iyy>
          <iyz>3.7754842412915678e-06</iyz>
          <izz>0.00056011394750397187</izz>
        </inertia>
      </inertial>
      <collision name='left_wrist_yaw_link_collision'>
        <pose>0 0 0 0 0 0</pose>
        <geometry>
          <mesh>
            <scale>1 1 1</scale>
            <uri>model://g1_description/meshes/left_wrist_yaw_link.STL</uri>
          </mesh>
        </geometry>
      </collision>
      <visual name='left_wrist_yaw_link_visual'>
        <pose>0 0 0 0 0 0</pose>
        <geometry>
          <mesh>
            <scale>1 1 1</scale>
            <uri>model://g1_description/meshes/left_wrist_yaw_link.STL</uri>
          </mesh>
        </geometry>
        <material>
          <diffuse>0.875 0.875 0.875 1</diffuse>
          <ambient>0.875 0.875 0.875 1</ambient>
        </material>
      </visual>
      <visual name='left_wrist_yaw_link_fixed_joint_lump__left_rubber_hand_visual_1'>
        <pose>0.041500000000000002 0.0030000000000000001 0 0 0 0</pose>
        <geometry>
          <mesh>
            <scale>1 1 1</scale>
            <uri>model://g1_description/meshes/left_rubber_hand.STL</uri>
          </mesh>
        </geometry>
        <material>
          <diffuse>0.875 0.875 0.875 1</diffuse>
          <ambient>0.875 0.875 0.875 1</ambient>
        </material>
      </visual>
    </link>
    <joint name='right_shoulder_pitch_joint' type='revolute'>
      <pose relative_to='torso_link'>0.0039563000000000003 -0.10020999999999999 0.24778 -0.27931000000000011 5.4949000000000032e-05 0.00019159</pose>
      <parent>torso_link</parent>
      <child>right_shoulder_pitch_link</child>
      <axis>
        <xyz>0 1 0</xyz>
        <limit>
          <lower>-3.0891999999999999</lower>
          <upper>2.6703999999999999</upper>
          <effort>25</effort>
          <velocity>37</velocity>
        </limit>
        <dynamics>
          <spring_reference>0</spring_reference>
          <spring_stiffness>0</spring_stiffness>
        </dynamics>
      </axis>
    </joint>
    <link name='right_shoulder_pitch_link'>
      <pose relative_to='right_shoulder_pitch_joint'>0 0 0 0 0 0</pose>
      <inertial>
        <pose>0 -0.035892 -0.011627999999999999 0 0 0</pose>
        <mass>0.71799999999999997</mass>
        <inertia>
          <ixx>0.00042910000000000002</ixx>
          <ixy>9.2e-06</ixy>
          <ixz>6.3999999999999997e-06</ixz>
          <iyy>0.00045300000000000001</iyy>
          <iyz>-2.26e-05</iyz>
          <izz>0.00042299999999999998</izz>
        </inertia>
      </inertial>
      <collision name='right_shoulder_pitch_link_collision'>
        <pose>0 -0.040000000000000001 -0.01 0 1.5707963267948966 0</pose>
        <geometry>
          <cylinder>
            <length>0.050000000000000003</length>
            <radius>0.029999999999999999</radius>
          </cylinder>
        </geometry>
      </collision>
      <visual name='right_shoulder_pitch_link_visual'>
        <pose>0 0 0 0 0 0</pose>
        <geometry>
          <mesh>
            <scale>1 1 1</scale>
            <uri>model://g1_description/meshes/right_shoulder_pitch_link.STL</uri>
          </mesh>
        </geometry>
        <material>
          <diffuse>0.875 0.875 0.875 1</diffuse>
          <ambient>0.875 0.875 0.875 1</ambient>
        </material>
      </visual>
    </link>
    <joint name='right_shoulder_roll_joint' type='revolute'>
      <pose relative_to='right_shoulder_pitch_link'>0 -0.037999999999999999 -0.013831 0.27925000000000011 0 0</pose>
      <parent>right_shoulder_pitch_link</parent>
      <child>right_shoulder_roll_link</child>
      <axis>
        <xyz>1 0 0</xyz>
        <limit>
          <lower>-2.2515000000000001</lower>
          <upper>1.5882000000000001</upper>
          <effort>25</effort>
          <velocity>37</velocity>
        </limit>
        <dynamics>
          <spring_reference>0</spring_reference>
          <spring_stiffness>0</spring_stiffness>
        </dynamics>
      </axis>
    </joint>
    <link name='right_shoulder_roll_link'>
      <pose relative_to='right_shoulder_roll_joint'>0 0 0 0 0 0</pose>
      <inertial>
        <pose>-0.00022699999999999999 -0.0072700000000000004 -0.063242999999999994 0 0 0</pose>
        <mass>0.64300000000000002</mass>
        <inertia>
          <ixx>0.0006177</ixx>
          <ixy>9.9999999999999995e-07</ixy>
          <ixz>8.6999999999999997e-06</ixz>
          <iyy>0.0006912</iyy>
          <iyz>5.3000000000000001e-06</iyz>
          <izz>0.00038939999999999998</izz>
        </inertia>
      </inertial>
      <collision name='right_shoulder_roll_link_collision'>
        <pose>-0.0040000000000000001 -0.0060000000000000001 -0.052999999999999999 0 0 0</pose>
        <geometry>
          <cylinder>
            <length>0.029999999999999999</length>
            <radius>0.029999999999999999</radius>
          </cylinder>
        </geometry>
      </collision>
      <visual name='right_shoulder_roll_link_visual'>
        <pose>0 0 0 0 0 0</pose>
        <geometry>
          <mesh>
            <scale>1 1 1</scale>
            <uri>model://g1_description/meshes/right_shoulder_roll_link.STL</uri>
          </mesh>
        </geometry>
        <material>
          <diffuse>0.875 0.875 0.875 1</diffuse>
          <ambient>0.875 0.875 0.875 1</ambient>
        </material>
      </visual>
    </link>
    <joint name='right_shoulder_yaw_joint' type='revolute'>
      <pose relative_to='right_shoulder_roll_link'>0 -0.0062399999999999999 -0.1032 0 0 0</pose>
      <parent>right_shoulder_roll_link</parent>
      <child>right_shoulder_yaw_link</child>
      <axis>
        <xyz>0 0 1</xyz>
        <limit>
          <lower>-2.6179999999999999</lower>
          <upper>2.6179999999999999</upper>
          <effort>25</effort>
          <velocity>37</velocity>
        </limit>
        <dynamics>
          <spring_reference>0</spring_reference>
          <spring_stiffness>0</spring_stiffness>
        </dynamics>
      </axis>
    </joint>
    <link name='right_shoulder_yaw_link'>
      <pose relative_to='right_shoulder_yaw_joint'>0 0 0 0 0 0</pose>
      <inertial>
        <pose>0.010773 0.0029489999999999998 -0.072009000000000004 0 0 0</pose>
        <mass>0.73399999999999999</mass>
        <inertia>
          <ixx>0.00099879999999999999</ixx>
          <ixy>-7.9000000000000006e-06</ixy>
          <ixz>0.00014119999999999999</ixz>
          <iyy>0.0010605</iyy>
          <iyz>2.8600000000000001e-05</iyz>
          <izz>0.00043540000000000001</izz>
        </inertia>
      </inertial>
      <collision name='right_shoulder_yaw_link_collision'>
        <pose>0 0 0 0 0 0</pose>
        <geometry>
          <mesh>
            <scale>1 1 1</scale>
            <uri>model://g1_description/meshes/right_shoulder_yaw_link.STL</uri>
          </mesh>
        </geometry>
      </collision>
      <visual name='right_shoulder_yaw_link_visual'>
        <pose>0 0 0 0 0 0</pose>
        <geometry>
          <mesh>
            <scale>1 1 1</scale>
            <uri>model://g1_description/meshes/right_shoulder_yaw_link.STL</uri>
          </mesh>
        </geometry>
        <material>
          <diffuse>0.875 0.875 0.875 1</diffuse>
          <ambient>0.875 0.875 0.875 1</ambient>
        </material>
      </visual>
    </link>
    <joint name='right_elbow_joint' type='revolute'>
      <pose relative_to='right_shoulder_yaw_link'>0.015782999999999998 0 -0.080518000000000006 0 0 0</pose>
      <parent>right_shoulder_yaw_link</parent>
      <child>right_elbow_link</child>
      <axis>
        <xyz>0 1 0</xyz>
        <limit>
          <lower>-1.0471999999999999</lower>
          <upper>2.0943999999999998</upper>
          <effort>25</effort>
          <velocity>37</velocity>
        </limit>
        <dynamics>
          <spring_reference>0</spring_reference>
          <spring_stiffness>0</spring_stiffness>
        </dynamics>
      </axis>
    </joint>
    <link name='right_elbow_link'>
      <pose relative_to='right_elbow_joint'>0 0 0 0 0 0</pose>
      <inertial>
        <pose>0.064956 -0.0044539999999999996 -0.010062 0 0 0</pose>
        <mass>0.59999999999999998</mass>
        <inertia>
          <ixx>0.00028909999999999998</ixx>
          <ixy>-6.5300000000000002e-05</ixy>
          <ixz>1.7200000000000001e-05</ixz>
          <iyy>0.00041520000000000001</iyy>
          <iyz>5.5999999999999997e-06</iyz>
          <izz>0.00041970000000000001</izz>
        </inertia>
      </inertial>
      <collision name='right_elbow_link_collision'>
        <pose>0 0 0 0 0 0</pose>
        <geometry>
          <mesh>
            <scale>1 1 1</scale>
            <uri>model://g1_description/meshes/right_elbow_link.STL</uri>
          </mesh>
        </geometry>
      </collision>
      <visual name='right_elbow_link_visual'>
        <pose>0 0 0 0 0 0</pose>
        <geometry>
          <mesh>
            <scale>1 1 1</scale>
            <uri>model://g1_description/meshes/right_elbow_link.STL</uri>
          </mesh>
        </geometry>
        <material>
          <diffuse>0.875 0.875 0.875 1</diffuse>
          <ambient>0.875 0.875 0.875 1</ambient>
        </material>
      </visual>
    </link>
    <joint name='right_wrist_roll_joint' type='revolute'>
      <pose relative_to='right_elbow_link'>0.10000000000000001 -0.00188791 -0.01 0 0 0</pose>
      <parent>right_elbow_link</parent>
      <child>right_wrist_roll_link</child>
      <axis>
        <xyz>1 0 0</xyz>
        <limit>
          <lower>-1.9722220539999999</lower>
          <upper>1.9722220539999999</upper>
          <effort>25</effort>
          <velocity>37</velocity>
        </limit>
        <dynamics>
          <spring_reference>0</spring_reference>
          <spring_stiffness>0</spring_stiffness>
        </dynamics>
      </axis>
    </joint>
    <link name='right_wrist_roll_link'>
      <pose relative_to='right_wrist_roll_joint'>0 0 0 0 0 0</pose>
      <inertial>
        <pose>0.017139447780000001 -0.00053759094000000005 4.8864000000000001e-07 0 0 0</pose>
        <mass>0.085444980000000004</mass>
        <inertia>
          <ixx>4.8215440230000001e-05</ixx>
          <ixy>4.2451102099999998e-06</ixy>
          <ixz>5.1059899999999997e-09</ixz>
          <iyy>3.7228990929999999e-05</iyy>
          <iyz>1.2352500000000001e-09</iyz>
          <izz>5.4821065410000003e-05</izz>
        </inertia>
      </inertial>
      <collision name='right_wrist_roll_link_collision'>
        <pose>0 0 0 0 0 0</pose>
        <geometry>
          <mesh>
            <scale>1 1 1</scale>
            <uri>model://g1_description/meshes/right_wrist_roll_link.STL</uri>
          </mesh>
        </geometry>
      </collision>
      <visual name='right_wrist_roll_link_visual'>
        <pose>0 0 0 0 0 0</pose>
        <geometry>
          <mesh>
            <scale>1 1 1</scale>
            <uri>model://g1_description/meshes/right_wrist_roll_link.STL</uri>
          </mesh>
        </geometry>
        <material>
          <diffuse>0.875 0.875 0.875 1</diffuse>
          <ambient>0.875 0.875 0.875 1</ambient>
        </material>
      </visual>
    </link>
    <joint name='right_wrist_pitch_joint' type='revolute'>
      <pose relative_to='right_wrist_roll_link'>0.037999999999999999 0 0 0 0 0</pose>
      <parent>right_wrist_roll_link</parent>
      <child>right_wrist_pitch_link</child>
      <axis>
        <xyz>0 1 0</xyz>
        <limit>
          <lower>-1.6144295580000001</lower>
          <upper>1.6144295580000001</upper>
          <effort>5</effort>
          <velocity>22</velocity>
        </limit>
        <dynamics>
          <spring_reference>0</spring_reference>
          <spring_stiffness>0</spring_stiffness>
        </dynamics>
      </axis>
    </joint>
    <link name='right_wrist_pitch_link'>
      <pose relative_to='right_wrist_pitch_joint'>0 0 0 0 0 0</pose>
      <inertial>
        <pose>0.022999898370000001 0.00111685314 -0.0011165809599999999 0 0 0</pose>
        <mass>0.48404955999999999</mass>
        <inertia>
          <ixx>0.00016579646273</ixx>
          <ixy>1.231206746e-05</ixy>
          <ixz>1.231699194e-05</ixz>
          <iyy>0.00042954057410000003</iyy>
          <iyz>-8.1417711999999998e-07</iyz>
          <izz>0.00042953697654000002</izz>
        </inertia>
      </inertial>
      <collision name='right_wrist_pitch_link_collision'>
        <pose>0 0 0 0 0 0</pose>
        <geometry>
          <mesh>
            <scale>1 1 1</scale>
            <uri>model://g1_description/meshes/right_wrist_pitch_link.STL</uri>
          </mesh>
        </geometry>
      </collision>
      <visual name='right_wrist_pitch_link_visual'>
        <pose>0 0 0 0 0 0</pose>
        <geometry>
          <mesh>
            <scale>1 1 1</scale>
            <uri>model://g1_description/meshes/right_wrist_pitch_link.STL</uri>
          </mesh>
        </geometry>
        <material>
          <diffuse>0.875 0.875 0.875 1</diffuse>
          <ambient>0.875 0.875 0.875 1</ambient>
        </material>
      </visual>
    </link>
    <joint name='right_wrist_yaw_joint' type='revolute'>
      <pose relative_to='right_wrist_pitch_link'>0.045999999999999999 0 0 0 0 0</pose>
      <parent>right_wrist_pitch_link</parent>
      <child>right_wrist_yaw_link</child>
      <axis>
        <xyz>0 0 1</xyz>
        <limit>
          <lower>-1.6144295580000001</lower>
          <upper>1.6144295580000001</upper>
          <effort>5</effort>
          <velocity>22</velocity>
        </limit>
        <dynamics>
          <spring_reference>0</spring_reference>
          <spring_stiffness>0</spring_stiffness>
        </dynamics>
      </axis>
    </joint>
    <link name='right_wrist_yaw_link'>
      <pose relative_to='right_wrist_yaw_joint'>0 0 0 0 0 0</pose>
      <inertial>
        <pose>0.070824430201051378 -0.00019174529120036591 0.0016174161391889761 0 0 0</pose>
        <mass>0.25457647</mass>
        <inertia>
          <ixx>0.00015044517917257641</ixx>
          <ixy>-3.7602754090026117e-05</ixy>
          <ixz>-2.9549415859057682e-06</ixz>
          <iyy>0.00064311326853337463</iyy>
          <iyz>-3.7754842412915678e-06</iyz>
          <izz>0.00056011394750397187</izz>
        </inertia>
      </inertial>
      <collision name='right_wrist_yaw_link_collision'>
        <pose>0 0 0 0 0 0</pose>
        <geometry>
          <mesh>
            <scale>1 1 1</scale>
            <uri>model://g1_description/meshes/right_wrist_yaw_link.STL</uri>
          </mesh>
        </geometry>
      </collision>
      <visual name='right_wrist_yaw_link_visual'>
        <pose>0 0 0 0 0 0</pose>
        <geometry>
          <mesh>
            <scale>1 1 1</scale>
            <uri>model://g1_description/meshes/right_wrist_yaw_link.STL</uri>
          </mesh>
        </geometry>
        <material>
          <diffuse>0.875 0.875 0.875 1</diffuse>
          <ambient>0.875 0.875 0.875 1</ambient>
        </material>
      </visual>
      <visual name='right_wrist_yaw_link_fixed_joint_lump__right_rubber_hand_visual_1'>
        <pose>0.041500000000000002 -0.0030000000000000001 0 0 0 0</pose>
        <geometry>
          <mesh>
            <scale>1 1 1</scale>
            <uri>model://g1_description/meshes/right_rubber_hand.STL</uri>
          </mesh>
        </geometry>
        <material>
          <diffuse>0.875 0.875 0.875 1</diffuse>
          <ambient>0.875 0.875 0.875 1</ambient>
        </material>
      </visual>
    </link>
    <frame name='imu_in_pelvis_joint' attached_to='pelvis'>
      <pose>0.045249999999999999 0 -0.083390000000000006 0 0 0</pose>
    </frame>
    <frame name='imu_in_pelvis' attached_to='imu_in_pelvis_joint'>
      <pose>0 0 0 0 0 0</pose>
    </frame>
    <frame name='pelvis_contour_joint' attached_to='pelvis'>
      <pose>0 0 0 0 0 0</pose>
    </frame>
    <frame name='pelvis_contour_link' attached_to='pelvis_contour_joint'>
      <pose>0 0 0 0 0 0</pose>
    </frame>
    <frame name='d435_joint' attached_to='torso_link'>
      <pose>0.057623500000000001 0.01753 0.42986999999999997 0 0.83077672394930091 0</pose>
    </frame>
    <frame name='d435_link' attached_to='d435_joint'>
      <pose>0 0 0 0 0 0</pose>
    </frame>
    <frame name='head_joint' attached_to='torso_link'>
      <pose>0.0039635 0 -0.043999999999999997 0 0 0</pose>
    </frame>
    <frame name='head_link' attached_to='head_joint'>
      <pose>0 0 0 0 0 0</pose>
    </frame>
    <frame name='imu_in_torso_joint' attached_to='torso_link'>
      <pose>-0.03959 -0.0022399999999999998 0.14792 0 0 0</pose>
    </frame>
    <frame name='imu_in_torso' attached_to='imu_in_torso_joint'>
      <pose>0 0 0 0 0 0</pose>
    </frame>
    <frame name='logo_joint' attached_to='torso_link'>
      <pose>0.0039635 0 -0.043999999999999997 0 0 0</pose>
    </frame>
    <frame name='logo_link' attached_to='logo_joint'>
      <pose>0 0 0 0 0 0</pose>
    </frame>
    <frame name='mid360_joint' attached_to='torso_link'>
      <pose>0.00028350000000000001 3.0000000000000001e-05 0.41617999999999999 0 0.040142572795869531 0</pose>
    </frame>
    <frame name='mid360_link' attached_to='mid360_joint'>
      <pose>0 0 0 0 0 0</pose>
    </frame>
    <frame name='left_hand_palm_joint' attached_to='left_wrist_yaw_link'>
      <pose>0.041500000000000002 0.0030000000000000001 0 0 0 0</pose>
    </frame>
    <frame name='left_rubber_hand' attached_to='left_hand_palm_joint'>
      <pose>0 0 0 0 0 0</pose>
    </frame>
    <frame name='right_hand_palm_joint' attached_to='right_wrist_yaw_link'>
      <pose>0.041500000000000002 -0.0030000000000000001 0 0 0 0</pose>
    </frame>
    <frame name='right_rubber_hand' attached_to='right_hand_palm_joint'>
      <pose>0 0 0 0 0 0</pose>
    </frame>
    <plugin filename="gz-sim-joint-state-publisher-system" name="gz::sim::systems::JointStatePublisher">
      <topic>/g1/joint_states</topic>
      <joint_name>left_hip_pitch_joint</joint_name>
      <joint_name>left_hip_roll_joint</joint_name>
      <joint_name>left_hip_yaw_joint</joint_name>
      <joint_name>left_knee_joint</joint_name>
      <joint_name>left_ankle_pitch_joint</joint_name>
      <joint_name>left_ankle_roll_joint</joint_name>
      <joint_name>right_hip_pitch_joint</joint_name>
      <joint_name>right_hip_roll_joint</joint_name>
      <joint_name>right_hip_yaw_joint</joint_name>
      <joint_name>right_knee_joint</joint_name>
      <joint_name>right_ankle_pitch_joint</joint_name>
      <joint_name>right_ankle_roll_joint</joint_name>
      <joint_name>waist_yaw_joint</joint_name>
      <joint_name>waist_roll_joint</joint_name>
      <joint_name>waist_pitch_joint</joint_name>
      <joint_name>left_shoulder_pitch_joint</joint_name>
      <joint_name>left_shoulder_roll_joint</joint_name>
      <joint_name>left_shoulder_yaw_joint</joint_name>
      <joint_name>left_elbow_joint</joint_name>
      <joint_name>left_wrist_roll_joint</joint_name>
      <joint_name>left_wrist_pitch_joint</joint_name>
      <joint_name>left_wrist_yaw_joint</joint_name>
      <joint_name>right_shoulder_pitch_joint</joint_name>
      <joint_name>right_shoulder_roll_joint</joint_name>
      <joint_name>right_shoulder_yaw_joint</joint_name>
      <joint_name>right_elbow_joint</joint_name>
      <joint_name>right_wrist_roll_joint</joint_name>
      <joint_name>right_wrist_pitch_joint</joint_name>
      <joint_name>right_wrist_yaw_joint</joint_name>
    </plugin>

    <plugin filename="gz-sim-joint-controller-system" name="gz::sim::systems::JointController"><joint_name>left_hip_pitch_joint</joint_name><topic>/g1/cmd_vel/left_hip_pitch_joint</topic></plugin>
    <plugin filename="gz-sim-joint-controller-system" name="gz::sim::systems::JointController"><joint_name>left_hip_roll_joint</joint_name><topic>/g1/cmd_vel/left_hip_roll_joint</topic></plugin>
    <plugin filename="gz-sim-joint-controller-system" name="gz::sim::systems::JointController"><joint_name>left_hip_yaw_joint</joint_name><topic>/g1/cmd_vel/left_hip_yaw_joint</topic></plugin>
    <plugin filename="gz-sim-joint-controller-system" name="gz::sim::systems::JointController"><joint_name>left_knee_joint</joint_name><topic>/g1/cmd_vel/left_knee_joint</topic></plugin>
    <plugin filename="gz-sim-joint-controller-system" name="gz::sim::systems::JointController"><joint_name>left_ankle_pitch_joint</joint_name><topic>/g1/cmd_vel/left_ankle_pitch_joint</topic></plugin>
    <plugin filename="gz-sim-joint-controller-system" name="gz::sim::systems::JointController"><joint_name>left_ankle_roll_joint</joint_name><topic>/g1/cmd_vel/left_ankle_roll_joint</topic></plugin>
    <plugin filename="gz-sim-joint-controller-system" name="gz::sim::systems::JointController"><joint_name>right_hip_pitch_joint</joint_name><topic>/g1/cmd_vel/right_hip_pitch_joint</topic></plugin>
    <plugin filename="gz-sim-joint-controller-system" name="gz::sim::systems::JointController"><joint_name>right_hip_roll_joint</joint_name><topic>/g1/cmd_vel/right_hip_roll_joint</topic></plugin>
    <plugin filename="gz-sim-joint-controller-system" name="gz::sim::systems::JointController"><joint_name>right_hip_yaw_joint</joint_name><topic>/g1/cmd_vel/right_hip_yaw_joint</topic></plugin>
    <plugin filename="gz-sim-joint-controller-system" name="gz::sim::systems::JointController"><joint_name>right_knee_joint</joint_name><topic>/g1/cmd_vel/right_knee_joint</topic></plugin>
    <plugin filename="gz-sim-joint-controller-system" name="gz::sim::systems::JointController"><joint_name>right_ankle_pitch_joint</joint_name><topic>/g1/cmd_vel/right_ankle_pitch_joint</topic></plugin>
    <plugin filename="gz-sim-joint-controller-system" name="gz::sim::systems::JointController"><joint_name>right_ankle_roll_joint</joint_name><topic>/g1/cmd_vel/right_ankle_roll_joint</topic></plugin>
    <plugin filename="gz-sim-joint-controller-system" name="gz::sim::systems::JointController"><joint_name>waist_yaw_joint</joint_name><topic>/g1/cmd_vel/waist_yaw_joint</topic></plugin>
    <plugin filename="gz-sim-joint-controller-system" name="gz::sim::systems::JointController"><joint_name>waist_roll_joint</joint_name><topic>/g1/cmd_vel/waist_roll_joint</topic></plugin>
    <plugin filename="gz-sim-joint-controller-system" name="gz::sim::systems::JointController"><joint_name>waist_pitch_joint</joint_name><topic>/g1/cmd_vel/waist_pitch_joint</topic></plugin>
    <plugin filename="gz-sim-joint-controller-system" name="gz::sim::systems::JointController"><joint_name>left_shoulder_pitch_joint</joint_name><topic>/g1/cmd_vel/left_shoulder_pitch_joint</topic></plugin>
    <plugin filename="gz-sim-joint-controller-system" name="gz::sim::systems::JointController"><joint_name>left_shoulder_roll_joint</joint_name><topic>/g1/cmd_vel/left_shoulder_roll_joint</topic></plugin>
    <plugin filename="gz-sim-joint-controller-system" name="gz::sim::systems::JointController"><joint_name>left_shoulder_yaw_joint</joint_name><topic>/g1/cmd_vel/left_shoulder_yaw_joint</topic></plugin>
    <plugin filename="gz-sim-joint-controller-system" name="gz::sim::systems::JointController"><joint_name>left_elbow_joint</joint_name><topic>/g1/cmd_vel/left_elbow_joint</topic></plugin>
    <plugin filename="gz-sim-joint-controller-system" name="gz::sim::systems::JointController"><joint_name>left_wrist_roll_joint</joint_name><topic>/g1/cmd_vel/left_wrist_roll_joint</topic></plugin>
    <plugin filename="gz-sim-joint-controller-system" name="gz::sim::systems::JointController"><joint_name>left_wrist_pitch_joint</joint_name><topic>/g1/cmd_vel/left_wrist_pitch_joint</topic></plugin>
    <plugin filename="gz-sim-joint-controller-system" name="gz::sim::systems::JointController"><joint_name>left_wrist_yaw_joint</joint_name><topic>/g1/cmd_vel/left_wrist_yaw_joint</topic></plugin>
    <plugin filename="gz-sim-joint-controller-system" name="gz::sim::systems::JointController"><joint_name>right_shoulder_pitch_joint</joint_name><topic>/g1/cmd_vel/right_shoulder_pitch_joint</topic></plugin>
    <plugin filename="gz-sim-joint-controller-system" name="gz::sim::systems::JointController"><joint_name>right_shoulder_roll_joint</joint_name><topic>/g1/cmd_vel/right_shoulder_roll_joint</topic></plugin>
    <plugin filename="gz-sim-joint-controller-system" name="gz::sim::systems::JointController"><joint_name>right_shoulder_yaw_joint</joint_name><topic>/g1/cmd_vel/right_shoulder_yaw_joint</topic></plugin>
    <plugin filename="gz-sim-joint-controller-system" name="gz::sim::systems::JointController"><joint_name>right_elbow_joint</joint_name><topic>/g1/cmd_vel/right_elbow_joint</topic></plugin>
    <plugin filename="gz-sim-joint-controller-system" name="gz::sim::systems::JointController"><joint_name>right_wrist_roll_joint</joint_name><topic>/g1/cmd_vel/right_wrist_roll_joint</topic></plugin>
    <plugin filename="gz-sim-joint-controller-system" name="gz::sim::systems::JointController"><joint_name>right_wrist_pitch_joint</joint_name><topic>/g1/cmd_vel/right_wrist_pitch_joint</topic></plugin>
    <plugin filename="gz-sim-joint-controller-system" name="gz::sim::systems::JointController"><joint_name>right_wrist_yaw_joint</joint_name><topic>/g1/cmd_vel/right_wrist_yaw_joint</topic></plugin>
  </model>
</sdf>
